Workbook

Sheet INSTRUCOES
B2: INFORMAÇÃO CONTÁBIL APLICADA À GESTÃO – UFAL Penedo
B3: Exercício Continuado – NexusTech Penedo Soluções Digitais Ltda.
B5: PROFESSOR | C5: Prof. Dr. Valber Gregory Barbosa Costa Bezerra Santos
B6: E-MAIL | C6: valber.santos@penedo.ufal.br
B7: DISCIPLINA | C7: SISB090 – Informação Contábil para Gestão
B8: PERÍODO | C8: 2026.1 – UFAL, Unidade Penedo
B9: PRAZO FINAL | C9: 22/06/2026
B11: OBJETIVO | C11: Registrar todos os lançamentos contábeis da NexusTech nos Meses 1, 2 e 3, elaborar os demonstrativos financeiros e calcular os índices.
B14: 📅 CRONOGRAMA DE ENTREGAS
B15: ENTREGA | C15: DESCRIÇÃO | D15: PRAZO | E15: FORMATO
B16: Entrega 1 | C16: Contrato Social simplificado da sua empresa | D16: 22/06/2026 | E16: PDF/Word
B17: Entrega 2 | C17: Planilha de lançamentos Mês 1 (mín. 10 transações) + Balancete | D17: 22/06/2026 | E17: Esta planilha
B18: Entrega 3 | C18: DRE e BP do Mês 1 + indicadores calculados | D18: 22/06/2026 | E18: Aba desta planilha
B19: Entrega 4 | C19: Planilha atualizada Mês 2 + análise comparativa Mês 1 vs. Mês 2 | D19: 22/06/2026 | E19: Esta planilha
B20: Entrega 5 | C20: Script Python + Banco de Dados SQLite (Aula 12) | D20: 22/06/2026 | E20: Pasta .zip
B21: Entrega 6 | C21: Sistema Contábil-Financeiro Python (Aula 13) | D21: 22/06/2026 | E21: Pasta .zip
B22: Entrega 7 | C22: Relatório Financeiro Final PDF + análise escrita (Aula 14) | D22: 22/06/2026 | E22: PDF + .zip
B24: 🎨 LEGENDA DE CORES
B25: Exemplo | C25: Células AZUIS em fundo AMARELO → Você deve preencher (input do aluno)
B26: Exemplo | C26: Células com fundo BRANCO e texto PRETO → Fórmulas automáticas
B27: Exemplo | C27: Células em fundo VERDE → Resultado / Saldo final
B28: Exemplo | C28: Células em fundo ROSA/VERMELHO → Atenção / Verificar
B29: Exemplo | C29: Células em fundo AZUL CLARO → Subtotais e totais

Sheet PLANO_CONTAS
B1: PLANO DE CONTAS SIMPLIFICADO – NexusTech
B2: Use EXATAMENTE estes nomes nas colunas conta_debito e conta_credito da planilha de lançamentos
B3: Código | C3: Conta (nome exato) | D3: Natureza | E3: Tipo Saldo | F3: Grupo na DRE/BP
B4: 1.1.01 | C4: Caixa | D4: Ativo Circulante | E4: Devedor | F4: BP – Ativo
B5: 1.1.02 | C5: Banco | D5: Ativo Circulante | E5: Devedor | F5: BP – Ativo
B6: 1.1.03 | C6: Clientes | D6: Ativo Circulante | E6: Devedor | F6: BP – Ativo
B7: 1.1.04 | C7: Adiantamentos | D7: Ativo Circulante | E7: Devedor | F7: BP – Ativo
B8: 1.2.01 | C8: Equipamentos de TI | D8: Ativo Não Circulante | E8: Devedor | F8: BP – Ativo
B9: 1.2.02 | C9: Moveis e Utensilios | D9: Ativo Não Circulante | E9: Devedor | F9: BP – Ativo
B10: 1.2.03 | C10: Depreciacao Acumulada | D10: Ativo Não Circulante | E10: Credor | F10: BP – Ativo (Retificadora)
B11: 2.1.01 | C11: DAS a Recolher | D11: Passivo Circulante | E11: Credor | F11: BP – Passivo
B12: 2.1.02 | C12: FGTS a Recolher | D12: Passivo Circulante | E12: Credor | F12: BP – Passivo
B13: 2.1.03 | C13: INSS a Recolher | D13: Passivo Circulante | E13: Credor | F13: BP – Passivo
B14: 2.1.04 | C14: Salarios a Pagar | D14: Passivo Circulante | E14: Credor | F14: BP – Passivo
... B29: 5.1.10 | C29: Desp. Pre-operacional | D29: Resultado – Despesa | E29: Devedor | F29: DRE – Despesa Oper.

Sheet LANCAMENTOS
B1: DIÁRIO DE LANÇAMENTOS – NexusTech Penedo Soluções Digitais Ltda.
B2: ⚠ REGRAS: (1) Preencha apenas células em AZUL/AMARELO (2) Nomes de contas IDÊNTICOS ao Plano de Contas (3) Datas: DD/MM/AAAA (4) Valores: números sem R$ ou vírgula
B3: Mês | C3: N.º Lanç. | D3: Data | E3: Doc. | F3: Descrição | G3: Conta Débito | H3: Conta Crédito | I3: Valor (R$) | J3: Histórico
B4: ◆ MÊS 1 – NexusTech Penedo Soluções Digitais Ltda.
B5: Mai | C5: 01 | D5: 01/05/2026 | E5: CS | F5: Integralização do capital social pelos sócios | G5: Banco | H5: Capital Social | I5: 50000 | J5: Marina 60% + Rafael 40%
B6: Mai | C6: 02 | D6: 02/05/2026 | E6: NF | F6: Compra de equipamentos (2 notebooks) à vista | G6: Equipamentos de TI | H6: Banco | I6: 8000 | J6: Nota Fiscal 001
B7: Mai | C7: 03 | D7: 02/05/2026 | E7: RC | F7: Pagamento de aluguel de sala – maio/2026 | G7: Desp. Aluguel | H7: Banco | I7: 1200 | J7: Contrato de locação
B8: Mai | C8: 04 | D8: 03/05/2026 | E8: RC | F8: Pagamento taxas de abertura – Junta/Alvará | G8: Desp. Pre-operacional | H8: Banco | I8: 350 | J8: Comprovante JUCAL
B9: Mai | C9: 05 | D9: 05/05/2026 | E9: REC | F9: Receita de consultoria – Cliente A (à vista) | G9: Banco | H9: Rec. Servicos | I9: 5000 | J9: Contrato Consultoria A
B10: Mai | C10: 06 | D10: 10/05/2026 | E10: NFS | F10: Receita de desenvolvimento – Cliente B (a prazo) | G10: Clientes | H10: Rec. Servicos | I10: 12000 | J10: NFS-e 0001 – venc. 10/06
B11: Mai | C11: 07 | D11: 31/05/2026 | E11: FP | F11: Salário do funcionário CLT – maio/2026 | G11: Desp. Salarios | H11: Banco | I11: 2500 | J11: Folha maio
B12: Mai | C12: 08 | D12: 31/05/2026 | E12: FP | F12: FGTS sobre salário (8%) – maio/2026 | G12: Desp. FGTS | H12: FGTS a Recolher | I12: 200 | J12: Guia FGTS maio
B13: Mai | C13: 09 | D13: 31/05/2026 | E13: FP | F13: INSS patronal (20%) sobre salário – maio/2026 | G13: Desp. INSS Patronal | H13: INSS a Recolher | I13: 500 | J13: GPS maio
B14: Mai | C14: 10 | D14: 31/05/2026 | E14: FP | F14: Pró-labore de Marina (administradora) – maio/2026 | G14: Desp. Pro-labore | H14: Banco | I14: 2490 | J14: Pró-labore líquido (desc. INSS 11%)
B15: Mai | C15: 10b | D15: 31/05/2026 | E15: FP | F15: INSS sobre pró-labore (11% sócio + 20% patronal) | G15: Desp. INSS Patronal | H15: INSS a Recolher | I15: 510 | J15: GPS pró-labore maio
B16: Mai | C16: 11 | D16: 31/05/2026 | E16: RC | F16: Material de escritório – maio/2026 | G16: Desp. Mat. Escritorio | H16: Banco | I16: 320 | J16: NF material escritório
... B20: Mai | C20: 15 | D20: 31/05/2026 | E20: AJ | F20: Depreciação equipamentos TI – maio/2026 | G20: Desp. Depreciacao | H20: Depreciacao Acumulada | I20: 133 | J20: R$8.000÷60 meses
B21: ◆ MÊS 2 – NexusTech Penedo Soluções Digitais Ltda.
B22: Jun | C22: 16 | D22: 05/06/2026 | E22: REC | F22: Receita de serviço – Cliente C (novo projeto, à vista) | G22: Banco | H22: Rec. Servicos | I22: 8500 | J22: NFS-e 0002
B23: Jun | C23: 17 | D23: 10/06/2026 | E23: NFS | F23: Receita – Cliente B (continuação projeto maio) | G23: Clientes | H23: Rec. Servicos | I23: 15000 | J23: NFS-e 0003
B24: Jun | C24: 15/05 | D24: 10/06/2026 | E24: REC | F24: Recebimento saldo Cliente B – maio | G24: Banco | H24: Clientes | I24: 6000 | J24: TED recebida saldo
B25: Jun | C25: 18 | D25: 30/06/2026 | E25: FP | F25: Salário funcionário CLT – junho/2026 | G25: Desp. Salarios | H25: Banco | I25: 2500 | J25: Folha junho
B26: Jun | C26: 19 | D26: 30/06/2026 | E26: FP | F26: FGTS (8%) + INSS patronal (20%) – junho/2026 | G26: Desp. INSS Patronal | H26: INSS a Recolher | I26: 700 | J26: Encargos junho
B27: Jun | C27: 20 | D27: 30/06/2026 | E27: FP | F27: Pró-labore Marina – junho/2026 | G27: Desp. Pro-labore | H27: Banco | I27: 2490 | J27: Pró-labore líquido
B28: Jun | C28: 21 | D28: 30/06/2026 | E28: RC | F28: Aluguel – junho/2026 | G28: Desp. Aluguel | H28: Banco | I28: 1200 | J28: Contrato locação
B29: Jun | C29: 22 | D29: 30/06/2026 | E29: RC | F29: Telecom + material escritório – junho/2026 | G29: Desp. Telecom | H29: Banco | I29: 600 | J29: Faturas operacionais
B30: Jun | C30: 23 | D30: 10/06/2026 | E30: GP | F30: Recolhimento DAS maio (do Passivo) | G30: DAS a Recolher | H30: Banco | I30: 1020 | J30: DARF DAS maio
B31: Jun | C31: 24 | D31: 10/06/2026 | E31: GP | F31: Recolhimento FGTS + INSS maio | G31: FGTS a Recolher | H31: Banco | I31: 1210 | J31: Guias maio
B32: Jun | C32: 25 | D32: 20/06/2026 | E32: NF | F32: Compra de mesa e cadeiras (ativo fixo) | G32: Moveis e Utensilios | H32: Banco | I32: 1500 | J32: NF mobiliário
B33: Jun | C33: 26 | D33: 30/06/2026 | E33: GIA | F33: DAS – Simples Nacional – junho/2026 | G33: Desp. Tributos | H33: DAS a Recolher | I33: 1410 | J33: RB R$23.500 × 6%
B34: Jun | C34: 27 | D34: 30/06/2026 | E34: AJ | F34: Depreciação equipamentos + móveis – junho/2026 | G34: Desp. Depreciacao | H34: Depreciacao Acumulada | I34: 158 | J34: Equiptos R$133 + Móv R$25
B35: ◆ MÊS 3 – NexusTech Penedo Soluções Digitais Ltda.
B36: Jul | C36: 28 | D36: 10/07/2026 | E36: REC | F36: Receita serviço – Cliente D (à vista) | G36: Banco | H36: Rec. Servicos | I36: 10000 | J36: NFS-e 0004 – preencher
B37: Jul | C37: 29 | D37: 10/07/2026 | E37: NFS | F37: Receita – Cliente B (3.º contrato, a prazo 45 dias) | G37: Clientes | H37: Rec. Servicos | I37: 18200 | J37: NFS-e 0005
B38: Jul | C38: 30 | D38: 31/07/2026 | E38: FP | F38: Salário – 2 funcionários CLT – julho/2026 | G38: Desp. Salarios | H38: Banco | I38: 5500 | J38: Folha julho (2 func.)
B39: Jul | C39: 31 | D39: 31/07/2026 | E39: FP | F39: FGTS + INSS patronal – julho/2026 | G39: Desp. INSS Patronal | H39: INSS a Recolher | I39: 1540 | J39: Encargos julho
B40: Jul | C40: 32 | D40: 31/07/2026 | E40: FP | F40: Pró-labore Marina – julho/2026 | G40: Desp. Pro-labore | H40: Banco | I40: 2490 | J40: Pró-labore líquido
B41: Jul | C41: 33 | D41: 31/07/2026 | E41: RC | F41: Aluguel – julho/2026 | G41: Desp. Aluguel | H41: Banco | I41: 1200 | J41: Contrato locação
B42: Jul | C42: 34 | D42: 31/07/2026 | E42: RC | F42: Telecom + escritório – julho/2026 | G42: Desp. Telecom | H42: Banco | I42: 650 | J42: Faturas operacionais
B43: Jul | C43: 35 | D43: 10/07/2026 | E43: GP | F43: Recolhimento DAS junho | G43: DAS a Recolher | H43: Banco | I43: 1410 | J43: DARF DAS junho
...

Sheet DRE
B1: DEMONSTRAÇÃO DO RESULTADO DO EXERCÍCIO – DRE
B2: NexusTech Penedo Soluções Digitais Ltda. | Período: Maio a Julho/2026
B3: Descrição | C3: Maio/2026 | D3: Junho/2026 | E3: Julho/2026 | F3: AV% Mai | G3: AV% Jun
B5: RECEITAS
B6: 1. Receita Bruta de Serviços | F6: 1 | G6: 1
B7: (–) DAS – Simples Nacional (6%) | F7: =IFERROR(C7/C6,"–") -> – | G7: =IFERROR(D7/D6,"–") -> –
B8: 2. RECEITA LÍQUIDA | C8: =C6+C7 -> 0 | D8: =D6+D7 -> 0 | E8: =E6+E7 -> 0 | F8: =IFERROR(C8/C6,"–") -> – | G8: =IFERROR(D8/D6,"–") -> –
B10: CUSTOS E DESPESAS OPERACIONAIS
B11: (–) Salários e FGTS | F11: =IFERROR(C11/C6,"–") -> – | G11: =IFERROR(D11/D6,"–") -> –
B12: (–) INSS Patronal (salário + pró-labore) | F12: =IFERROR(C12/C6,"–") -> – | G12: =IFERROR(D12/D6,"–") -> –
B13: (–) Pró-labore (administradora) | F13: =IFERROR(C13/C6,"–") -> – | G13: =IFERROR(D13/D6,"–") -> –
B14: (–) Aluguel | F14: =IFERROR(C14/C6,"–") -> – | G14: =IFERROR(D14/D6,"–") -> –
B15: (–) Telecomunicações | F15: =IFERROR(C15/C6,"–") -> – | G15: =IFERROR(D15/D6,"–") -> –
B16: (–) Material de Escritório | F16: =IFERROR(C16/C6,"–") -> – | G16: =IFERROR(D16/D6,"–") -> –
B17: (–) Despesas Pré-operacionais | F17: =IFERROR(C17/C6,"–") -> – | G17: =IFERROR(D17/D6,"–") -> –
B18: (–) Depreciação de Equipamentos | F18: =IFERROR(C18/C6,"–") -> – | G18: =IFERROR(D18/D6,"–") -> –
B19: 3. TOTAL DESPESAS OPERACIONAIS | C19: =SUM(C11:C18) -> 0 | D19: =SUM(D11:D18) -> 0 | E19: =SUM(E11:E18) -> 0 | F19: =IFERROR(IF(C6<>0,C19/C6,0),"–") -> 0 | G19: =IFERROR(IF(D6<>0,D19/D6,0),"–") -> 0
B21: 4. RESULTADO OPERACIONAL (EBIT) | C21: =C8+C19 -> 0 | D21: =D8+D19 -> 0 | E21: =E8+E19 -> 0 | F21: =IFERROR(IF(C6<>0,C21/C6,0),"–") -> 0 | G21: =IFERROR(IF(D6<>0,D21/D6,0),"–") -> 0
B22: (+/–) Resultado Financeiro | F22: =IFERROR(C22/C6,"–") -> – | G22: =IFERROR(D22/D6,"–") -> –
B23: 5. LAIR (Lucro Antes do IR) | C23: =C21+C22 -> 0 | D23: =D21+D22 -> 0 | E23: =E21+E22 -> 0 | F23: =IFERROR(IF(C6<>0,C23/C6,0),"–") -> 0 | G23: =IFERROR(IF(D6<>0,D23/D6,0),"–") -> 0
B24: (–) IRPJ / CSLL (Simples – já no DAS) | F24: =IFERROR(C24/C6,"–") -> – | G24: =IFERROR(D24/D6,"–") -> –
B25: LUCRO LÍQUIDO DO EXERCÍCIO ✓ | C25: =C23+C24 -> 0 | D25: =D23+D24 -> 0 | E25: =E23+E24 -> 0 | F25: =IFERROR(IF(C6<>0,C25/C6,0),"–") -> 0 | G25: =IFERROR(IF(D6<>0,D25/D6,0),"–") -> 0
B27: Nota: Valores em AZUL/AMARELO devem ser preenchidos pelo aluno. Valores em PRETO são calculados automaticamente. AV% = Análise Vertical em relação à Receita Bruta.

Sheet BALANCO_PATRIMONIAL
B1: BALANÇO PATRIMONIAL – NexusTech Penedo Soluções Digitais Ltda.
B2: ATIVO | C2: Maio/2026 | D2: Jun/2026 | E2: Jul/2026 | G2: PASSIVO + PL | H2: Maio/2026 | I2: Jun/2026 | J2: Jul/2026
B3: ATIVO CIRCULANTE | G3: PASSIVO CIRCULANTE
B4: Caixa | G4: DAS a Recolher
B5: Banco | G5: FGTS a Recolher
B6: Clientes (a receber) | G6: INSS a Recolher
B7: Adiantamentos | G7: Salários a Pagar
B8: TOTAL ATIVO CIRCULANTE | C8: =SUM(C4:C7) -> 0 | D8: =SUM(D4:D7) -> 0 | E8: =SUM(E4:E7) -> 0 | G8: Aluguéis a Pagar
G9: TOTAL PASSIVO CIRCULANTE | H9: =SUM(H4:H8) -> 0 | I9: =SUM(I4:I8) -> 0 | J9: =SUM(J4:J8) -> 0
B10: ATIVO NÃO CIRCULANTE
B11: Equipamentos de TI | G11: PASSIVO NÃO CIRCULANTE
B12: Móveis e Utensílios | G12: Empréstimos LP
B13: (–) Depreciação Acumulada | G13: TOTAL PNC | H13: =H12 -> 0 | I13: =I12 -> 0 | J13: =J12 -> 0
B14: TOTAL ATIVO NÃO CIRCULANTE | C14: =SUM(C11:C13) -> 0 | D14: =SUM(D11:D13) -> 0 | E14: =SUM(E11:E13) -> 0
G15: PATRIMÔNIO LÍQUIDO
B16: TOTAL GERAL DO ATIVO | C16: =C8+C14 -> 0 | D16: =D8+D14 -> 0 | E16: =E8+E14 -> 0 | G16: Capital Social
G17: Lucros Acumulados
G18: TOTAL PL | H18: =H16+H17 -> 0 | I18: =I16+I17 -> 0 | J18: =J16+J17 -> 0
G20: TOTAL PASSIVO + PL | H20: =H9+H13+H18 -> 0 | I20: =I9+I13+I18 -> 0 | J20: =J9+J13+J18 -> 0
B23: ✔ VERIFICAÇÃO: Ativo deve ser igual a Passivo + PL
B24: Diferença Maio (deve ser R$ 0,00): | C24: =IFERROR(C16-H20,0) -> 0
B25: Diferença Junho (deve ser R$ 0,00): | D25: =IFERROR(D16-I20,0) -> 0
B26: Diferença Julho (deve ser R$ 0,00): | E26: =IFERROR(E16-J20,0) -> 0

Sheet INDICES_FINANCEIROS
B1: ANÁLISE DE ÍNDICES FINANCEIROS – NexusTech Penedo
B2: ⚠ Preencha os valores do BP e DRE nas abas correspondentes. Os índices são calculados automaticamente a partir dos dados lançados.
B3: Índice | C3: Fórmula | D3: Maio/2026 | E3: Jun/2026 | F3: Jul/2026 | G3: Referência | H3: Interpretação
B4: ÍNDICES DE LIQUIDEZ
B5: Liquidez Corrente | C5: AC ÷ PC | D5: =IFERROR(BALANCO_PATRIMONIAL!C8/BALANCO_PATRIMONIAL!H9,0) -> 0 | E5: =IFERROR(BALANCO_PATRIMONIAL!D8/BALANCO_PATRIMONIAL!I9,0) -> 0 | F5: =IFERROR(BALANCO_PATRIMONIAL!E8/BALANCO_PATRIMONIAL!J9,0) -> 0 | G5: > 1,5 (ótimo) | H5: Quanto > 1, maior a folga de curto prazo
B6: Liquidez Seca | C6: (AC – Estoques) ÷ PC | D6: =IFERROR(BALANCO_PATRIMONIAL!C8/BALANCO_PATRIMONIAL!H9,0) -> 0 | E6: =IFERROR(BALANCO_PATRIMONIAL!D8/BALANCO_PATRIMONIAL!I9,0) -> 0 | F6: =IFERROR(BALANCO_PATRIMONIAL!E8/BALANCO_PATRIMONIAL!J9,0) -> 0 | G6: > 1,0 | H6: Sem estoque (serviços) = igual à LC
B7: Liquidez Imediata | C7: (Caixa + Banco) ÷ PC | D7: =IFERROR(BALANCO_PATRIMONIAL!C5/BALANCO_PATRIMONIAL!H9,0) -> 0 | E7: =IFERROR(BALANCO_PATRIMONIAL!D5/BALANCO_PATRIMONIAL!I9,0) -> 0 | F7: =IFERROR(BALANCO_PATRIMONIAL!E5/BALANCO_PATRIMONIAL!J9,0) -> 0 | G7: > 0,5 | H7: Capacidade de pagamento imediato
B9: ÍNDICES DE RENTABILIDADE
B10: Margem Bruta | C10: Lucro Bruto ÷ Receita Líquida | D10: =IFERROR(DRE!C25/DRE!C6,0) -> 0 | E10: =IFERROR(DRE!D25/DRE!D6,0) -> 0 | F10: =IFERROR(DRE!E25/DRE!E6,0) -> 0 | G10: Quanto maior, melhor | H10: 100% para empresas de serviços puro
B11: Margem Operacional (EBIT) | C11: EBIT ÷ Receita Líquida | D11: =IFERROR(DRE!C22/DRE!C8,"–") -> – | E11: =IFERROR(DRE!D22/DRE!D8,"–") -> – | F11: =IFERROR(DRE!E22/DRE!E8,"–") -> – | G11: > 15% saudável | H11: Eficiência das operações
B12: Margem Líquida | C12: Lucro Líquido ÷ Receita Bruta | D12: =IFERROR(DRE!C26/DRE!C6,"–") -> – | E12: =IFERROR(DRE!D26/DRE!D6,"–") -> – | F12: =IFERROR(DRE!E26/DRE!E6,"–") -> – | G12: > 10% saudável | H12: Quanto sobra de cada R$1 faturado
B13: ROE – Retorno s/ PL | C13: Lucro Líquido ÷ PL | D13: =IFERROR(DRE!C25/BALANCO_PATRIMONIAL!H18,0) -> 0 | E13: =IFERROR(DRE!D25/BALANCO_PATRIMONIAL!I18,0) -> 0 | F13: =IFERROR(DRE!E25/BALANCO_PATRIMONIAL!J18,0) -> 0 | G13: > 12% a.a. | H13: Retorno gerado para os sócios
B14: ROA – Retorno s/ Ativo Total | C14: Lucro Líquido ÷ Ativo Total | D14: =IFERROR(DRE!C25/BALANCO_PATRIMONIAL!C16,0) -> 0 | E14: =IFERROR(DRE!D25/BALANCO_PATRIMONIAL!D16,0) -> 0 | F14: =IFERROR(DRE!E25/BALANCO_PATRIMONIAL!E16,0) -> 0 | G14: > 8% a.a. | H14: Eficiência de todos os ativos
B16: ÍNDICES DE ESTRUTURA DE CAPITAL
B17: Endividamento Geral | C17: Passivo Total ÷ Ativo Total | D17: =IFERROR(BALANCO_PATRIMONIAL!H20/BALANCO_PATRIMONIAL!C16,0) -> 0 | E17: =IFERROR(BALANCO_PATRIMONIAL!I20/BALANCO_PATRIMONIAL!D16,0) -> 0 | F17: =IFERROR(BALANCO_PATRIMONIAL!J20/BALANCO_PATRIMONIAL!E16,0) -> 0 | G17: < 50% saudável | H17: Quanto do ativo é financiado por terceiros
B18: Grau de Alavancagem Financeira | C18: Passivo Total ÷ PL | D18: =IFERROR(BALANCO_PATRIMONIAL!H17/BALANCO_PATRIMONIAL!H16,"–") -> – | E18: =IFERROR(BALANCO_PATRIMONIAL!I17/BALANCO_PATRIMONIAL!I16,"–") -> – | F18: =IFERROR(BALANCO_PATRIMONIAL!J17/BALANCO_PATRIMONIAL!J16,"–") -> – | G18: < 1,0 conservador | H18: Relação dívida / capital próprio
D19: =IFERROR(BALANCO_PATRIMONIAL!H20/BALANCO_PATRIMONIAL!H18,0) -> 0 | E19: =IFERROR(BALANCO_PATRIMONIAL!I20/BALANCO_PATRIMONIAL!I18,0) -> 0 | F19: =IFERROR(BALANCO_PATRIMONIAL!J20/BALANCO_PATRIMONIAL!J18,0) -> 0
B20: ÍNDICES DE ATIVIDADE
B21: Giro do Ativo | C21: Receita Líquida ÷ Ativo Total | D21: =IFERROR(DRE!C8/BALANCO_PATRIMONIAL!C16,0) -> 0 | E21: =IFERROR(DRE!D8/BALANCO_PATRIMONIAL!D16,0) -> 0 | F21: =IFERROR(DRE!E8/BALANCO_PATRIMONIAL!E16,0) -> 0 | G21: > 0,5 | H21: Eficiência na geração de receita
B22: PMRV – Prazo Médio Receb. | C22: (Clientes ÷ Receita Bruta) × 30 | D22: =IFERROR(BALANCO_PATRIMONIAL!C6/DRE!C6*30,0) -> 0 | E22: =IFERROR(BALANCO_PATRIMONIAL!D6/DRE!D6*30,0) -> 0 | F22: =IFERROR(BALANCO_PATRIMONIAL!E6/DRE!E6*30,0) -> 0 | G22: < 30 dias ideal | H22: Quanto tempo leva para receber

Sheet BALANCETE
B1: BALANCETE DE VERIFICAÇÃO – NexusTech (Meses 1, 2 e 3)
B2: Conta | C2: Nat. | D2: Débitos (R$) | E2: Créditos (R$) | F2: Saldo (R$) | G2: D/C
B3: Maio/2026 – Mês 1
B4: Banco | C4: Ativo | F4: =D4-E4 -> 0 | G4: D
B5: Clientes | C5: Ativo | F5: =D5-E5 -> 0 | G5: D
B6: Equipamentos de TI | C6: Ativo | F6: =D6-E6 -> 0 | G6: D
B7: Depreciação Acumulada | C7: Retif. Ativo | F7: =E7-D7 -> 0 | G7: C
B8: DAS a Recolher | C8: Passivo | F8: =E8-D8 -> 0 | G8: C
B9: FGTS a Recolher | C9: Passivo | F9: =E9-D9 -> 0 | G9: C
B10: INSS a Recolher | C10: Passivo | F10: =E10-D10 -> 0 | G10: C
B11: Capital Social | C11: PL | F11: =E11-D11 -> 0 | G11: C
B12: Rec. Servicos | C12: Resultado | F12: =E12-D12 -> 0 | G12: C
B13: Desp. Salarios | C13: Resultado | F13: =D13-E13 -> 0 | G13: D
B14: Desp. FGTS | C14: Resultado | F14: =D14-E14 -> 0 | G14: D
B15: Desp. INSS Patronal | C15: Resultado | F15: =D15-E15 -> 0 | G15: D
B16: Desp. Pro-labore | C16: Resultado | F16: =D16-E16 -> 0 | G16: D
B17: Desp. Aluguel | C17: Resultado | F17: =D17-E17 -> 0 | G17: D
B18: Desp. Telecom | C18: Resultado | F18: =D18-E18 -> 0 | G18: D
B19: Desp. Mat. Escritorio | C19: Resultado | F19: =D19-E19 -> 0 | G19: D
B20: Desp. Pre-operacional | C20: Resultado | F20: =D20-E20 -> 0 | G20: D
B21: Desp. Tributos | C21: Resultado | F21: =D21-E21 -> 0 | G21: D
B22: Desp. Depreciacao | C22: Resultado | F22: =D22-E22 -> 0 | G22: D
B24: TOTAIS DO BALANCETE – VERIFICAÇÃO
B25: TOTAL CRÉDITOS | D25: =SUM(D4:D23) -> 0 | E25: =SUM(E4:E23) -> 0
B26: Se Total Débitos = Total Créditos → Balancete correto (princípio das partidas dobradas)

Sheet ANALISE_E_GRAFICOS
B1: ANÁLISE COMPARATIVA E DASHBOARD DE INDICADORES
B2: EVOLUÇÃO DOS INDICADORES (Meses 1, 2 e 3)
B3: Indicador | C3: Maio/2026 | D3: Jun/2026 | E3: Jul/2026
B4: Receita Bruta (R$) | C4: =IFERROR(DRE!C6,"–") -> 0 | D4: =IFERROR(DRE!D6,"–") -> 0 | E4: =IFERROR(DRE!E6,"–") -> 0
B5: Receita Líquida (R$) | C5: =IFERROR(DRE!C8,"–") -> 0 | D5: =IFERROR(DRE!D8,"–") -> 0 | E5: =IFERROR(DRE!E8,"–") -> 0
B6: Despesas Operacionais (R$) | C6: =IFERROR(DRE!C20,"–") -> 0 | D6: =IFERROR(DRE!D20,"–") -> 0 | E6: =IFERROR(DRE!E20,"–") -> 0
B7: Lucro Líquido (R$) | C7: =IFERROR(DRE!C26,"–") -> 0 | D7: =IFERROR(DRE!D26,"–") -> 0 | E7: =IFERROR(DRE!E26,"–") -> 0
B8: Margem Líquida (%) | C8: =IFERROR(INDICES_FINANCEIROS!D10,"–") -> 0 | D8: =IFERROR(INDICES_FINANCEIROS!E10,"–") -> 0 | E8: =IFERROR(INDICES_FINANCEIROS!F10,"–") -> 0
B9: Liquidez Corrente | C9: =IFERROR(INDICES_FINANCEIROS!D5,"–") -> 0 | D9: =IFERROR(INDICES_FINANCEIROS!E5,"–") -> 0 | E9: =IFERROR(INDICES_FINANCEIROS!F5,"–") -> 0
B10: ROE (%) | C10: =IFERROR(INDICES_FINANCEIROS!D13,"–") -> 0 | D10: =IFERROR(INDICES_FINANCEIROS!E13,"–") -> 0 | E10: =IFERROR(INDICES_FINANCEIROS!F13,"–") -> 0
B11: Endividamento Geral (%) | C11: =IFERROR(INDICES_FINANCEIROS!D18,"–") -> – | D11: =IFERROR(INDICES_FINANCEIROS!E18,"–") -> – | E11: =IFERROR(INDICES_FINANCEIROS!F18,"–") -> –
B12: PMRV (dias) | C12: =IFERROR(INDICES_FINANCEIROS!D22,"–") -> 0 | D12: =IFERROR(INDICES_FINANCEIROS!E22,"–") -> 0 | E12: =IFERROR(INDICES_FINANCEIROS!F22,"–") -> 0
B14: ANÁLISE HORIZONTAL – VARIAÇÕES
B15: Indicador | C15: Var. Mai→Jun | D15: Var. Jun→Jul | E15: Var. Total
B16: Receita Bruta | C16: =IFERROR((D4-C4)/ABS(C4),0) -> 0 | D16: =IFERROR((E4-D4)/ABS(D4),0) -> 0 | E16: =IFERROR((E4-C4)/ABS(C4),0) -> 0
B17: Receita Líquida | C17: =IFERROR((D5-C5)/ABS(C5),0) -> 0 | D17: =IFERROR((E5-D5)/ABS(D5),0) -> 0 | E17: =IFERROR((E5-C5)/ABS(C5),0) -> 0
B18: Desp. Operacionais | C18: =IFERROR((D6-C6)/ABS(C6),0) -> 0 | D18: =IFERROR((E6-D6)/ABS(D6),0) -> 0 | E18: =IFERROR((E6-C6)/ABS(C6),0) -> 0
B19: Lucro Líquido | C19: =IFERROR((D7-C7)/ABS(C7),0) -> 0 | D19: =IFERROR((E7-D7)/ABS(D7),0) -> 0 | E19: =IFERROR((E7-C7)/ABS(C7),0) -> 0
B20: Margem Líquida | C20: =IFERROR((D8-C8)/ABS(C8),0) -> 0 | D20: =IFERROR((E8-D8)/ABS(D8),0) -> 0 | E20: =IFERROR((E8-C8)/ABS(C8),0) -> 0
C21: =IFERROR((D9-C9)/ABS(C9),0) -> 0 | D21: =IFERROR((E9-D9)/ABS(D9),0) -> 0 | E21: =IFERROR((E9-C9)/ABS(C9),0) -> 0
B23: ANÁLISE GERENCIAL (texto livre do aluno)
B24: Pontos Fortes identificados: 1. 2.
B26: Pontos de Atenção / Riscos: 1. 2.
